<robot name = "robot">
    <link name="Torso">
        <inertial>
            <origin xyz="0.0 0 0.8267639560396718" rpy="0 0 0"/>
            <mass value="1" />
            <inertia ixx="100" ixy="0" ixz="0" iyy="100" iyz="0" izz="100" />
        </inertial>
        <visual>
            <origin xyz="0.0 0 0.8267639560396718" rpy="0 0 0"/>
            <geometry>
                <box size="1 1 1" />
            </geometry>
            <material name="Cyan">
                <color rgba="0 1.0 1.0 1.0"/>
            </material>
        </visual>
        <collision>
            <origin xyz="0.0 0 0.8267639560396718" rpy="0 0 0"/>
            <geometry>
                <box size="1 1 1" />
            </geometry>
        </collision>
    </link>
    <joint name="Torso_FrontLeg" type="revolute">
       <parent link="Torso"/>
       <child  link="FrontLeg"/>
       <origin rpy="0 0 0" xyz="0 0.5 0.8267639560396718"/>
     <axis xyz="1 0 0"/>
       <limit effort="0.0" lower="-3.14159" upper="3.14159" velocity="0.0"/>
    </joint>
    <link name="FrontLeg">
        <inertial>
            <origin xyz="0 1.375203292982981 0" rpy="0 0 0"/>
            <mass value="1" />
            <inertia ixx="100" ixy="0" ixz="0" iyy="100" iyz="0" izz="100" />
        </inertial>
        <visual>
            <origin xyz="0 1.375203292982981 0" rpy="0 0 0"/>
            <geometry>
                <box size="0.2 2.750406585965962 0.2" />
            </geometry>
            <material name="Cyan">
                <color rgba="0 1.0 1.0 1.0"/>
            </material>
        </visual>
        <collision>
            <origin xyz="0 1.375203292982981 0" rpy="0 0 0"/>
            <geometry>
                <box size="0.2 2.750406585965962 0.2" />
            </geometry>
        </collision>
    </link>
    <joint name="Torso_BackLeg" type="revolute">
       <parent link="Torso"/>
       <child  link="BackLeg"/>
       <origin rpy="0 0 0" xyz="0 -0.5 0.8267639560396718"/>
     <axis xyz="1 0 0"/>
       <limit effort="0.0" lower="-3.14159" upper="3.14159" velocity="0.0"/>
    </joint>
    <link name="BackLeg">
        <inertial>
            <origin xyz="0 -1.375203292982981 0" rpy="0 0 0"/>
            <mass value="1" />
            <inertia ixx="100" ixy="0" ixz="0" iyy="100" iyz="0" izz="100" />
        </inertial>
        <visual>
            <origin xyz="0 -1.375203292982981 0" rpy="0 0 0"/>
            <geometry>
                <box size="0.2 2.750406585965962 0.2" />
            </geometry>
            <material name="Cyan">
                <color rgba="0 1.0 1.0 1.0"/>
            </material>
        </visual>
        <collision>
            <origin xyz="0 -1.375203292982981 0" rpy="0 0 0"/>
            <geometry>
                <box size="0.2 2.750406585965962 0.2" />
            </geometry>
        </collision>
    </link>
    <joint name="Torso_LeftLeg" type="revolute">
       <parent link="Torso"/>
       <child  link="LeftLeg"/>
       <origin rpy="0 0 0" xyz="-0.5 0 0.8267639560396718"/>
     <axis xyz="0 1 0"/>
       <limit effort="0.0" lower="-3.14159" upper="3.14159" velocity="0.0"/>
    </joint>
    <link name="LeftLeg">
        <inertial>
            <origin xyz="-1.375203292982981 0 0" rpy="0 0 0"/>
            <mass value="1" />
            <inertia ixx="100" ixy="0" ixz="0" iyy="100" iyz="0" izz="100" />
        </inertial>
        <visual>
            <origin xyz="-1.375203292982981 0 0" rpy="0 0 0"/>
            <geometry>
                <box size="2.750406585965962 0.2 0.2" />
            </geometry>
            <material name="Cyan">
                <color rgba="0 1.0 1.0 1.0"/>
            </material>
        </visual>
        <collision>
            <origin xyz="-1.375203292982981 0 0" rpy="0 0 0"/>
            <geometry>
                <box size="2.750406585965962 0.2 0.2" />
            </geometry>
        </collision>
    </link>
    <joint name="Torso_RightLeg" type="revolute">
       <parent link="Torso"/>
       <child  link="RightLeg"/>
       <origin rpy="0 0 0" xyz="0.5 0 0.8267639560396718"/>
     <axis xyz="0 1 0"/>
       <limit effort="0.0" lower="-3.14159" upper="3.14159" velocity="0.0"/>
    </joint>
    <link name="RightLeg">
        <inertial>
            <origin xyz="1.375203292982981 0 0" rpy="0 0 0"/>
            <mass value="1" />
            <inertia ixx="100" ixy="0" ixz="0" iyy="100" iyz="0" izz="100" />
        </inertial>
        <visual>
            <origin xyz="1.375203292982981 0 0" rpy="0 0 0"/>
            <geometry>
                <box size="2.750406585965962 0.2 0.2" />
            </geometry>
            <material name="Cyan">
                <color rgba="0 1.0 1.0 1.0"/>
            </material>
        </visual>
        <collision>
            <origin xyz="1.375203292982981 0 0" rpy="0 0 0"/>
            <geometry>
                <box size="2.750406585965962 0.2 0.2" />
            </geometry>
        </collision>
    </link>
    <joint name="FrontLeg_LowerFrontLeg" type="revolute">
       <parent link="FrontLeg"/>
       <child  link="LowerFrontLeg"/>
       <origin rpy="0 0 0" xyz="0 2.750406585965962 0"/>
     <axis xyz="1 0 0"/>
       <limit effort="0.0" lower="-3.14159" upper="3.14159" velocity="0.0"/>
    </joint>
    <link name="LowerFrontLeg">
        <inertial>
            <origin xyz="0 0 -0.4133819780198359" rpy="0 0 0"/>
            <mass value="1" />
            <inertia ixx="100" ixy="0" ixz="0" iyy="100" iyz="0" izz="100" />
        </inertial>
        <visual>
            <origin xyz="0 0 -0.4133819780198359" rpy="0 0 0"/>
            <geometry>
                <box size="0.2 0.2 0.8267639560396718" />
            </geometry>
            <material name="Cyan">
                <color rgba="0 1.0 1.0 1.0"/>
            </material>
        </visual>
        <collision>
            <origin xyz="0 0 -0.4133819780198359" rpy="0 0 0"/>
            <geometry>
                <box size="0.2 0.2 0.8267639560396718" />
            </geometry>
        </collision>
    </link>
    <joint name="BackLeg_LowerBackLeg" type="revolute">
       <parent link="BackLeg"/>
       <child  link="LowerBackLeg"/>
       <origin rpy="0 0 0" xyz="0 -2.750406585965962 0"/>
     <axis xyz="1 0 0"/>
       <limit effort="0.0" lower="-3.14159" upper="3.14159" velocity="0.0"/>
    </joint>
    <link name="LowerBackLeg">
        <inertial>
            <origin xyz="0 0 -0.4133819780198359" rpy="0 0 0"/>
            <mass value="1" />
            <inertia ixx="100" ixy="0" ixz="0" iyy="100" iyz="0" izz="100" />
        </inertial>
        <visual>
            <origin xyz="0 0 -0.4133819780198359" rpy="0 0 0"/>
            <geometry>
                <box size="0.2 0.2 0.8267639560396718" />
            </geometry>
            <material name="Cyan">
                <color rgba="0 1.0 1.0 1.0"/>
            </material>
        </visual>
        <collision>
            <origin xyz="0 0 -0.4133819780198359" rpy="0 0 0"/>
            <geometry>
                <box size="0.2 0.2 0.8267639560396718" />
            </geometry>
        </collision>
    </link>
    <joint name="LeftLeg_LowerLeftLeg" type="revolute">
       <parent link="LeftLeg"/>
       <child  link="LowerLeftLeg"/>
       <origin rpy="0 0 0" xyz="-2.750406585965962 0 0"/>
     <axis xyz="0 1 0"/>
       <limit effort="0.0" lower="-3.14159" upper="3.14159" velocity="0.0"/>
    </joint>
    <link name="LowerLeftLeg">
        <inertial>
            <origin xyz="0 0 -0.4133819780198359" rpy="0 0 0"/>
            <mass value="1" />
            <inertia ixx="100" ixy="0" ixz="0" iyy="100" iyz="0" izz="100" />
        </inertial>
        <visual>
            <origin xyz="0 0 -0.4133819780198359" rpy="0 0 0"/>
            <geometry>
                <box size="0.2 0.2 0.8267639560396718" />
            </geometry>
            <material name="Cyan">
                <color rgba="0 1.0 1.0 1.0"/>
            </material>
        </visual>
        <collision>
            <origin xyz="0 0 -0.4133819780198359" rpy="0 0 0"/>
            <geometry>
                <box size="0.2 0.2 0.8267639560396718" />
            </geometry>
        </collision>
    </link>
    <joint name="RightLeg_LowerRightLeg" type="revolute">
       <parent link="RightLeg"/>
       <child  link="LowerRightLeg"/>
       <origin rpy="0 0 0" xyz="2.750406585965962 0 0"/>
     <axis xyz="0 1 0"/>
       <limit effort="0.0" lower="-3.14159" upper="3.14159" velocity="0.0"/>
    </joint>
    <link name="LowerRightLeg">
        <inertial>
            <origin xyz="0 0 -0.4133819780198359" rpy="0 0 0"/>
            <mass value="1" />
            <inertia ixx="100" ixy="0" ixz="0" iyy="100" iyz="0" izz="100" />
        </inertial>
        <visual>
            <origin xyz="0 0 -0.4133819780198359" rpy="0 0 0"/>
            <geometry>
                <box size="0.2 0.2 0.8267639560396718" />
            </geometry>
            <material name="Cyan">
                <color rgba="0 1.0 1.0 1.0"/>
            </material>
        </visual>
        <collision>
            <origin xyz="0 0 -0.4133819780198359" rpy="0 0 0"/>
            <geometry>
                <box size="0.2 0.2 0.8267639560396718" />
            </geometry>
        </collision>
    </link>
</robot>